<robot name="onshape">
<link name="kicker_base">
<visual>
<origin xyz="-0.012500000000000011102 0 0.15000000000000007772" rpy="0 -0 0" />
<geometry>
<mesh filename="package://isaac_cam_conveyor/urdf/kicker/kicker_base.stl"/>
</geometry>
<material name="kicker_base_material">
<color rgba="0.61568627450980395466 0.81176470588235294379 0.92941176470588238168 1.0"/>
</material>
</visual>
<collision>
<origin xyz="-0.012500000000000011102 0 0.15000000000000007772" rpy="0 -0 0" />
<geometry>
<mesh filename="package://isaac_cam_conveyor/urdf/kicker/kicker_base.stl"/>
</geometry>
</collision>
<inertial>
<origin xyz="0 0 0" rpy="0 0 0"/>
<mass value="0" />
<inertia ixx="0" ixy="0"  ixz="0" iyy="0" iyz="0" izz="0" />
</inertial>
</link>

<link name="kicker_arm">
<visual>
<origin xyz="0.39999999999999991118 0 -0.024999999999999911182" rpy="-1.570796326794896558 -1.570796326794896558 0" />
<geometry>
<mesh filename="package://isaac_cam_conveyor/urdf/kicker/kicker_arm.stl"/>
</geometry>
<material name="kicker_arm_material">
<color rgba="0.64705882352941179736 0.64705882352941179736 0.64705882352941179736 1.0"/>
</material>
</visual>
<collision>
<origin xyz="0.39999999999999991118 0 -0.024999999999999911182" rpy="-1.570796326794896558 -1.570796326794896558 0" />
<geometry>
<mesh filename="package://isaac_cam_conveyor/urdf/kicker/kicker_arm.stl"/>
</geometry>
</collision>
<inertial>
<origin xyz="0 0 0" rpy="0 0 0"/>
<mass value="0" />
<inertia ixx="0" ixy="0"  ixz="0" iyy="0" iyz="0" izz="0" />
</inertial>
</link>

<joint name="kicker_joint" type="prismatic">
<origin xyz="0.012499999999999955591 -0.39999999999999991118 0.15000000000000007772" rpy="1.570796326794896558 -0 1.570796326794896558" />
<parent link="kicker_base" />
<child link="kicker_arm" />
<axis xyz="0 0 1"/>
<limit effort="1" velocity="20" lower="0" upper="1.1999999999999999556"/>
<joint_properties friction="0.0"/>
</joint>


</robot>
